<robot name="arduinobot">

    <link name="world"/>

    <link name="base_link">
        <visual>
            <origin rpy="0 0 0" xyz="-0.5 -0.5 0"/>
            <geometry>
                <mesh filename="basement.STL"/>
            </geometry>
        </visual>
        <collision>
            <origin rpy="0 0 0" xyz="-0.5 -0.5 0"/>
            <geometry>
                <mesh filename="basement.STL"/>
            </geometry>
        </collision>
    </link>

    <joint name="virtual_joint" type="fixed">
        <parent link="world"/>
        <child link="base_link"/>
        <origin xyz="0 0 0" rpy="0 0 0"/>
    </joint> 

    <joint name ="joint_1" type="revolute">
        <parent link="base_link"/>
        <child link = "base_plate"/>
        <origin xyz="0 0 0.307"/>
        <axis xyz="0 0 1"/>
    </joint>

</robot>
