<?xml version="1.0" encoding="utf-8" ?>
<!-- =================================================================================== -->
<!-- |    This document was autogenerated by xacro from /home/ubuntu/arduinobot/src/arduinobot_description/src/urdf/arduinobot.urdf.xacro | -->
<!-- |    EDITING THIS FILE BY HAND IS NOT RECOMMENDED                                 | -->
<!-- =================================================================================== -->
<robot name="arduinobot">
    <!-- Links -->
    <link name="world" />
    <link name="base_link">
        <visual>
            <origin rpy="0 0 0" xyz="-0.5 -0.5 0" />
            <geometry>
                <mesh filename="package://arduinobot_description/src/mesh/basement.STL" scale="0.01 0.01 0.01" />
            </geometry>
        </visual>
        <collision>
            <origin rpy="0 0 0" xyz="-0.5 -0.5 0" />
            <geometry>
                <mesh filename="package://arduinobot_description/src/mesh/basement.STL" scale="0.01 0.01 0.01" />
            </geometry>
        </collision>
        
<inertial>
            <mass value="0.1" />
            <inertia ixx="0.03" iyy="0.03" izz="0.03" ixy="0.0" ixz="0.0" iyz="0.0" />
        </inertial>

    </link>
    <link name="base_plate">
        <visual>
            <origin rpy="0 0 0" xyz="-0.39 -0.39 -0.56" />
            <geometry>
                <mesh filename="package://arduinobot_description/src/mesh/base_plate.STL" scale="0.01 0.01 0.01" />
            </geometry>
        </visual>
        <collision>
            <origin rpy="0 0 0" xyz="-0.39 -0.39 -0.56" />
            <geometry>
                <mesh filename="package://arduinobot_description/src/mesh/round_plate.STL" scale="0.01 0.01 0.01" />
            </geometry>
        </collision>
        
<inertial>
            <mass value="0.1" />
            <inertia ixx="0.03" iyy="0.03" izz="0.03" ixy="0.0" ixz="0.0" iyz="0.0" />
        </inertial>

    </link>
    <link name="forward_drive_arm">
        <visual>
            <origin rpy=" 0 -1.5707963268 1.5707963268" xyz="0.19 0.06 -0.08" />
            <geometry>
                <mesh filename="package://arduinobot_description/src/mesh/forward_drive_arm.STL" scale="0.01 0.01 0.01" />
            </geometry>
        </visual>
        <collision>
            <origin rpy=" 0 -1.5707963268 1.5707963268" xyz="0.19 0.06 -0.08" />
            <geometry>
                <mesh filename="package://arduinobot_description/src/mesh/forward_drive_arm.STL" scale="0.01 0.01 0.01" />
            </geometry>
        </collision>
        
<inertial>
            <mass value="0.1" />
            <inertia ixx="0.03" iyy="0.03" izz="0.03" ixy="0.0" ixz="0.0" iyz="0.0" />
        </inertial>

    </link>
    <link name="horizontal_arm">
        <visual>
            <origin rpy="1.5707963268 0 1.5707963268" xyz="-0.03 -0.4 -0.06" />
            <geometry>
                <mesh filename="package://arduinobot_description/src/mesh/horizontal_arm.STL" scale="0.01 0.01 0.01" />
            </geometry>
        </visual>
        <collision>
            <origin rpy="1.5707963268 0 1.5707963268" xyz="-0.03 -0.4 -0.06" />
            <geometry>
                <mesh filename="package://arduinobot_description/src/mesh/horizontal_arm.STL" scale="0.01 0.01 0.01" />
            </geometry>
        </collision>
        
<inertial>
            <mass value="0.1" />
            <inertia ixx="0.03" iyy="0.03" izz="0.03" ixy="0.0" ixz="0.0" iyz="0.0" />
        </inertial>

    </link>
    <link name="claw_support">
        <visual>
            <origin rpy="0 0 1.5707963268" xyz="0 -0.05 -0.15" />
            <geometry>
                <mesh filename="package://arduinobot_description/src/mesh/claw_support.STL" scale="0.01 0.01 0.01" />
            </geometry>
        </visual>
        <collision>
            <origin rpy="0 0 1.5707963268" xyz="0 -0.05 -0.15" />
            <geometry>
                <mesh filename="package://arduinobot_description/src/mesh/claw_support.STL" scale="0.01 0.01 0.01" />
            </geometry>
        </collision>
        
<inertial>
            <mass value="0.1" />
            <inertia ixx="0.03" iyy="0.03" izz="0.03" ixy="0.0" ixz="0.0" iyz="0.0" />
        </inertial>

    </link>
    <link name="gripper_right">
        <visual>
            <origin rpy="0 0 -1.5707963268" xyz="-0.1 0.50 -0.1" />
            <geometry>
                <mesh filename="package://arduinobot_description/src/mesh/right_finger.STL" scale="0.01 0.01 0.01" />
            </geometry>
        </visual>
        <collision>
            <origin rpy="0 0 -1.5707963268" xyz="-0.1 0.50 -0.1" />
            <geometry>
                <mesh filename="package://arduinobot_description/src/mesh/right_finger.STL" scale="0.01 0.01 0.01" />
            </geometry>
        </collision>
        
<inertial>
            <mass value="0.1" />
            <inertia ixx="0.03" iyy="0.03" izz="0.03" ixy="0.0" ixz="0.0" iyz="0.0" />
        </inertial>

    </link>
    <link name="gripper_left">
        <visual>
            <origin rpy="0 0 -1.5707963268" xyz="-0.04 0.50 -0.1" />
            <geometry>
                <mesh filename="package://arduinobot_description/src/mesh/left_finger.STL" scale="0.01 0.01 0.01" />
            </geometry>
        </visual>
        <collision>
            <origin rpy="0 0 -1.5707963268" xyz="-0.2 0.50 -0.1" />
            <geometry>
                <mesh filename="package://arduinobot_description/src/mesh/left_finger.STL" scale="0.01 0.01 0.01" />
            </geometry>
        </collision>
        
<inertial>
            <mass value="0.1" />
            <inertia ixx="0.03" iyy="0.03" izz="0.03" ixy="0.0" ixz="0.0" iyz="0.0" />
        </inertial>

    </link>
    <link name="tool_link" />
    <!-- Joints -->
    <joint name="joint_world" type="fixed">
        <parent link="world" />
        <child link="base_link" />
        <origin rpy="0 0 0" xyz="0 0 0" />
    </joint>
    <joint name="joint_1" type="revolute">
        <parent link="base_link" />
        <child link="base_plate" />
        <origin xyz="0 0 0.307" />
        <axis xyz="0 0 1" />
        <limit effort="1000.0" lower="-1.5707963268" upper="1.5707963268" velocity="0.5" />
    </joint>
    <joint name="joint_2" type="revolute">
        <parent link="base_plate" />
        <child link="forward_drive_arm" />
        <origin xyz="0 0 0.28" />
        <axis xyz="1 0 0" />
        <limit effort="1000.0" lower="-1.5707963268" upper="1.5707963268" velocity="0.5" />
    </joint>
    <joint name="joint_3" type="revolute">
        <parent link="forward_drive_arm" />
        <child link="horizontal_arm" />
        <origin xyz="0 0 0.8" />
        <axis xyz="1 0 0" />
        <limit effort="1000.0" lower="-1.5707963268" upper="1.5707963268" velocity="0.5" />
    </joint>
    <joint name="horizontal_arm_to_claw_support" type="fixed">
        <parent link="horizontal_arm" />
        <child link="claw_support" />
        <origin xyz="0 0.82 0" />
    </joint>
    <joint name="joint_4" type="revolute">
        <parent link="claw_support" />
        <child link="gripper_right" />
        <origin xyz="-0.04 0.13 -0.1" />
        <axis xyz="0 0 1" />
        <limit effort="1000.0" lower="-1.5707963268" upper="0" velocity="0.5" />
    </joint>
    <joint name="joint_5" type="revolute">
        <parent link="claw_support" />
        <child link="gripper_left" />
        <origin xyz="-0.22 0.13 -0.1" />
        <axis xyz="0 0 1" />
        <limit effort="1000.0" lower="0" upper="1.5707963268" velocity="0.5" />
        <mimic joint="joint_4" multiplier="-1" offset="0" />
    </joint>
    <joint name="gripper_right_to_tool" type="fixed">
        <parent link="gripper_right" />
        <child link="tool_link" />
        <origin xyz="0 0 0" />
    </joint>
    <!-- Transmissions-->
    
<transmission name="transmission_1">
        <type>transmission_interface/SimpleTransmission</type>
        <joint name="joint_1">
            <hardwareInterface>PositionJointInterface</hardwareInterface>
        </joint>
        <actuator name="motor_1">
            <hardwareInterface>PositionJointInterface</hardwareInterface>
            <mechanicalReduction>1</mechanicalReduction>
        </actuator>
    </transmission>
    <transmission name="transmission_2">
        <type>transmission_interface/SimpleTransmission</type>
        <joint name="joint_2">
            <hardwareInterface>PositionJointInterface</hardwareInterface>
        </joint>
        <actuator name="motor_2">
            <hardwareInterface>PositionJointInterface</hardwareInterface>
            <mechanicalReduction>1</mechanicalReduction>
        </actuator>
    </transmission>
    <transmission name="transmission_3">
        <type>transmission_interface/SimpleTransmission</type>
        <joint name="joint_3">
            <hardwareInterface>PositionJointInterface</hardwareInterface>
        </joint>
        <actuator name="motor_3">
            <hardwareInterface>PositionJointInterface</hardwareInterface>
            <mechanicalReduction>1</mechanicalReduction>
        </actuator>
    </transmission>
    <transmission name="transmission_4">
        <type>transmission_interface/SimpleTransmission</type>
        <joint name="joint_4">
            <hardwareInterface>PositionJointInterface</hardwareInterface>
        </joint>
        <actuator name="motor_4">
            <hardwareInterface>PositionJointInterface</hardwareInterface>
            <mechanicalReduction>1</mechanicalReduction>
        </actuator>
    </transmission>
    <!-- Gazebo Configuration section -->
    <gazebo>
        <plugin filename="libgazebo_ros_control.so" name="gazebo_ros_control">
            <robotNamespace>/arduinobot</robotNamespace>
            <robotSimType>gazbo_roscontrol/DefaultRobotHWSim</robotSimType>
        </plugin>
    </gazebo>
    <transmission name="trans_joint_1">
        <type>transmission_interface/SimpleTransmission</type>
        <joint name="joint_1">
            <hardwareInterface>hardware_interface/PositionJointInterface</hardwareInterface>
        </joint>
        <actuator name="joint_1_motor">
            <hardwareInterface>hardware_interface/PositionJointInterface</hardwareInterface>
            <mechanicalReduction>1</mechanicalReduction>
        </actuator>
    </transmission>
    <transmission name="trans_joint_2">
        <type>transmission_interface/SimpleTransmission</type>
        <joint name="joint_2">
            <hardwareInterface>hardware_interface/PositionJointInterface</hardwareInterface>
        </joint>
        <actuator name="joint_2_motor">
            <hardwareInterface>hardware_interface/PositionJointInterface</hardwareInterface>
            <mechanicalReduction>1</mechanicalReduction>
        </actuator>
    </transmission>
    <transmission name="trans_joint_3">
        <type>transmission_interface/SimpleTransmission</type>
        <joint name="joint_3">
            <hardwareInterface>hardware_interface/PositionJointInterface</hardwareInterface>
        </joint>
        <actuator name="joint_3_motor">
            <hardwareInterface>hardware_interface/PositionJointInterface</hardwareInterface>
            <mechanicalReduction>1</mechanicalReduction>
        </actuator>
    </transmission>
    <transmission name="trans_joint_4">
        <type>transmission_interface/SimpleTransmission</type>
        <joint name="joint_4">
            <hardwareInterface>hardware_interface/EffortJointInterface</hardwareInterface>
        </joint>
        <actuator name="joint_4_motor">
            <hardwareInterface>hardware_interface/EffortJointInterface</hardwareInterface>
            <mechanicalReduction>1</mechanicalReduction>
        </actuator>
    </transmission>
    <transmission name="trans_joint_5">
        <type>transmission_interface/SimpleTransmission</type>
        <joint name="joint_5">
            <hardwareInterface>hardware_interface/EffortJointInterface</hardwareInterface>
        </joint>
        <actuator name="joint_5_motor">
            <hardwareInterface>hardware_interface/EffortJointInterface</hardwareInterface>
            <mechanicalReduction>1</mechanicalReduction>
        </actuator>
    </transmission>
    <gazebo>
        <plugin name="gazebo_ros_control" filename="libgazebo_ros_control.so">
            <robotNamespace>/</robotNamespace>
        </plugin>
    </gazebo>
</robot>