<?xml version="1.0" encoding="utf-8"?>
<!-- =================================================================================== -->
<!-- |    This document was autogenerated by xacro from arduinobot.urdf.xacro          | -->
<!-- |    EDITING THIS FILE BY HAND IS NOT RECOMMENDED                                 | -->
<!-- =================================================================================== -->
<robot name="arduinobot">
  <!-- Links -->
  <link name="world"/>
  <link name="base_link">
    <visual>
      <origin rpy="0 0 0" xyz="-0.5 -0.5 0"/>
      <geometry>
        <mesh filename="package://simple_robot_arm/mesh/basement.STL" scale="0.01 0.01 0.01"/>
      </geometry>
    </visual>
    <collision>
      <origin rpy="0 0 0" xyz="-0.5 -0.5 0"/>
      <geometry>
        <mesh filename="package://simple_robot_arm/mesh/basement.STL" scale="0.01 0.01 0.01"/>
      </geometry>
    </collision>
  </link>
  <link name="base_plate">
    <visual>
      <origin rpy="0 0 0" xyz="-0.39 -0.39 -0.56"/>
      <geometry>
        <mesh filename="package://simple_robot_arm/mesh/base_plate.STL" scale="0.01 0.01 0.01"/>
      </geometry>
    </visual>
    <collision>
      <origin rpy="0 0 0" xyz="-0.39 -0.39 -0.56"/>
      <geometry>
        <mesh filename="package://simple_robot_arm/mesh/round_plate.STL" scale="0.01 0.01 0.01"/>
      </geometry>
    </collision>
  </link>
  <link name="forward_drive_arm">
    <visual>
      <origin rpy=" 0 -1.5707963268 1.5707963268" xyz="0.19 0.06 -0.08"/>
      <geometry>
        <mesh filename="package://simple_robot_arm/mesh/forward_drive_arm.STL" scale="0.01 0.01 0.01"/>
      </geometry>
    </visual>
    <collision>
      <origin rpy=" 0 -1.5707963268 1.5707963268" xyz="0.19 0.06 -0.08"/>
      <geometry>
        <mesh filename="package://simple_robot_arm/mesh/forward_drive_arm.STL" scale="0.01 0.01 0.01"/>
      </geometry>
    </collision>
  </link>
  <link name="horizontal_arm">
    <visual>
      <origin rpy="1.5707963268 0 1.5707963268" xyz="-0.03 -0.4 -0.06"/>
      <geometry>
        <mesh filename="package://simple_robot_arm/mesh/horizontal_arm.STL" scale="0.01 0.01 0.01"/>
      </geometry>
    </visual>
    <collision>
      <origin rpy="1.5707963268 0 1.5707963268" xyz="-0.03 -0.4 -0.06"/>
      <geometry>
        <mesh filename="package://simple_robot_arm/mesh/horizontal_arm.STL" scale="0.01 0.01 0.01"/>
      </geometry>
    </collision>
  </link>
  <link name="claw_support">
    <visual>
      <origin rpy="0 0 1.5707963268" xyz="0 -0.05 -0.15"/>
      <geometry>
        <mesh filename="package://simple_robot_arm/mesh/claw_support.STL" scale="0.01 0.01 0.01"/>
      </geometry>
    </visual>
    <collision>
      <origin rpy="0 0 1.5707963268" xyz="0 -0.05 -0.15"/>
      <geometry>
        <mesh filename="package://simple_robot_arm/mesh/claw_support.STL" scale="0.01 0.01 0.01"/>
      </geometry>
    </collision>
  </link>
  <link name="tool_link"/>
  <!-- Joints -->
  <joint name="joint_world" type="fixed">
    <parent link="world"/>
    <child link="base_link"/>
    <origin rpy="0 0 0" xyz="0 0 0"/>
  </joint>
  <joint name="joint_1" type="revolute">
    <parent link="base_link"/>
    <child link="base_plate"/>
    <origin xyz="0 0 0.307"/>
    <axis xyz="0 0 1"/>
    <limit effort="1000.0" lower="-1.5707963268" upper="1.5707963268" velocity="0.5"/>
  </joint>
  <joint name="joint_2" type="revolute">
    <parent link="base_plate"/>
    <child link="forward_drive_arm"/>
    <origin xyz="0 0 0.28"/>
    <axis xyz="1 0 0"/>
    <limit effort="1000.0" lower="-1.5707963268" upper="1.5707963268" velocity="0.5"/>
  </joint>
  <joint name="joint_3" type="revolute">
    <parent link="forward_drive_arm"/>
    <child link="horizontal_arm"/>
    <origin xyz="0 0 0.8"/>
    <axis xyz="1 0 0"/>
    <limit effort="1000.0" lower="-1.5707963268" upper="1.5707963268" velocity="0.5"/>
  </joint>
  <joint name="horizontal_arm_to_claw_support" type="fixed">
    <parent link="horizontal_arm"/>
    <child link="claw_support"/>
    <origin xyz="0 0.82 0"/>
  </joint>
  <joint name="claw_support_to_tool" type="fixed">
    <parent link="claw_support"/>
    <child link="tool_link"/>
    <origin xyz="0 0 0"/>
  </joint>
  <!-- Transmissions-->
  <transmission name="transmission_1">
    <type>transmission_interface/SimpleTransmission</type>
    <joint name="joint_1">
      <hardwareInterface>PositionJointInterface</hardwareInterface>
    </joint>
    <actuator name="motor_1">
      <hardwareInterface>PositionJointInterface</hardwareInterface>
      <mechanicalReduction>1</mechanicalReduction>
    </actuator>
  </transmission>
  <transmission name="transmission_2">
    <type>transmission_interface/SimpleTransmission</type>
    <joint name="joint_2">
      <hardwareInterface>PositionJointInterface</hardwareInterface>
    </joint>
    <actuator name="motor_2">
      <hardwareInterface>PositionJointInterface</hardwareInterface>
      <mechanicalReduction>1</mechanicalReduction>
    </actuator>
  </transmission>
  <transmission name="transmission_3">
    <type>transmission_interface/SimpleTransmission</type>
    <joint name="joint_3">
      <hardwareInterface>PositionJointInterface</hardwareInterface>
    </joint>
    <actuator name="motor_3">
      <hardwareInterface>PositionJointInterface</hardwareInterface>
      <mechanicalReduction>1</mechanicalReduction>
    </actuator>
  </transmission>
</robot>
